Warning: No logger found for thread 8677455936
Warning: No logger found for thread 8677455936
Traceback (most recent call last):
  File "/Users/satoshinakamoto/Documents/AtlasInfinity/dgm/self_improve_step.py", line 425, in <module>
    main()
  File "/Users/satoshinakamoto/Documents/AtlasInfinity/dgm/self_improve_step.py", line 413, in main
    metadata = self_improve(
  File "/Users/satoshinakamoto/Documents/AtlasInfinity/dgm/self_improve_step.py", line 278, in self_improve
    container = build_dgm_container(client=client, force_rebuild=force_rebuild)
  File "/Users/satoshinakamoto/Documents/AtlasInfinity/dgm/utils/docker_utils.py", line 118, in build_dgm_container
    image, logs = client.images.build(path=repo_path, tag=image_name, rm=True)
  File "/Users/satoshinakamoto/Documents/AtlasInfinity/dgm/venv/lib/python3.10/site-packages/docker/models/images.py", line 296, in build
    resp = self.client.api.build(**kwargs)
  File "/Users/satoshinakamoto/Documents/AtlasInfinity/dgm/venv/lib/python3.10/site-packages/docker/api/build.py", line 159, in build
    context = utils.tar(
  File "/Users/satoshinakamoto/Documents/AtlasInfinity/dgm/venv/lib/python3.10/site-packages/docker/utils/build.py", line 35, in tar
    return create_archive(
  File "/Users/satoshinakamoto/Documents/AtlasInfinity/dgm/venv/lib/python3.10/site-packages/docker/utils/build.py", line 103, in create_archive
    t.addfile(i, f)
  File "/Users/satoshinakamoto/.pyenv/versions/3.10.14/lib/python3.10/tarfile.py", line 2208, in addfile
    copyfileobj(fileobj, self.fileobj, tarinfo.size, bufsize=bufsize)
  File "/Users/satoshinakamoto/.pyenv/versions/3.10.14/lib/python3.10/tarfile.py", line 255, in copyfileobj
    dst.write(buf)
  File "/Users/satoshinakamoto/.pyenv/versions/3.10.14/lib/python3.10/tempfile.py", line 499, in func_wrapper
    return func(*args, **kwargs)
KeyboardInterrupt
